Workbook

Sheet data
A1: CellProfiler | B1: FAST | C1: SuperSegger | D1: Oufti
A2: -86.073054 | B2: -18.460334 | C2: -38.872537 | D2: -73.48144
A3: 47.469887 | B3: 62.642052 | C3: -57.260163 | D3: 79.315414
A4: 59.81794 | B4: 12.712234 | C4: 69.1489 | D4: 82.782444
A5: 74.058913 | B5: 32.36787 | C5: 11.104159 | D5: -77.651789
A6: 64.970466 | B6: 35.717815 | C6: 7.015056 | D6: 61.514352
A7: 81.660417 | B7: 31.248364 | C7: 75.606244 | D7: -78.223658
A8: 55.528349 | B8: 53.089398 | C8: -62.903259 | D8: -63.432091
A9: 46.460884 | B9: -47.48325 | C9: -15.901615 | D9: -53.632207
A10: 64.403872 | B10: 39.028281 | C10: 62.259212 | D10: 71.866798
A11: -81.509719 | B11: 48.174109 | C11: -33.589211 | D11: 68.450769
A12: -83.583444 | B12: 34.784178 | C12: -14.978335 | D12: -75.688842
A13: -26.317963 | B13: 42.296762 | C13: -71.58025 | D13: -56.89768
... A274: 34.521782 | B274: 0.15141223 | C274: -16.307622 | D274: -87.247055
A275: -35.594089 | B275: -35.749083 | C275: -26.817867
A276: -83.0869 | B276: -24.411363 | C276: -48.141866
A277: -85.416566 | B277: 35.41296 | C277: -8.5798171
A278: 37.502391 | B278: -62.056504 | C278: 14.162867
A279: 50.93513 | B279: 28.807705 | C279: -44.820215
A280: 55.92488 | B280: -17.38189 | C280: -13.122594
A281: 0.83530296 | B281: -66.450035 | C281: -24.231967
A282: 48.760483 | B282: 58.598723 | C282: -0.47890272
A283: 31.902839 | B283: 50.396214 | C283: 23.778307
A284: -34.425797 | B284: 32.179424 | C284: 18.56832
A285: -83.101703 | B285: -6.3036152 | C285: 11.373242
A286: -76.249098 | B286: -48.66375 | C286: 15.706844
... A1193: 73.311582 | B1193: -10.448102 | C1193: 50.717628
A1194: -33.594539 | C1194: -1.2303435
A1195: 54.73638 | C1195: 48.922575
A1196: -60.886143 | C1196: 10.627612
A1197: 55.056136 | C1197: 31.269922
A1198: 49.105851 | C1198: -29.511919
A1199: 70.546939 | C1199: 43.643107
A1200: 76.362195 | C1200: 22.284553
A1201: 59.521963 | C1201: 64.962445
A1202: 79.064707 | C1202: 33.375436
A1203: 78.010607 | C1203: 29.05166
A1204: 11.716849 | C1204: 18.010844
A1205: 26.166329 | C1205: 30.283051
... A4621: -77.28848 | C4621: 8.7055477
...

Sheet plot
A1: Bins | B1: Lable | C1: CellProfiler | D1: FAST | E1: SuperSegger | F1: Oufti
A2: =MIN(data!A2:D6155) -> -90 | B2: =MAX(data!A2:D6155) -> 89.703503
A3: =A2+3 -> -87 | B3: =CONCATENATE(ROUND(A2,2),"-",ROUND(A3,2)) -> -90--87 | C3: =SUM(COUNTIF(data!A$2:A$6155,CONCATENATE("=",$A2)),COUNTIF(data!A$2:A$6155,CONCATENATE(">",$A2))-COUNTIF(data!A$2:A$6155,CONCATENATE(">",$A3))) -> 26 | D3: =SUM(COUNTIF(data!B$2:B$6155,CONCATENATE("=",$A2)),COUNTIF(data!B$2:B$6155,CONCATENATE(">",$A2))-COUNTIF(data!B$2:B$6155,CONCATENATE(">",$A3))) -> 1 | E3: =SUM(COUNTIF(data!C$2:C$6155,CONCATENATE("=",$A2)),COUNTIF(data!C$2:C$6155,CONCATENATE(">",$A2))-COUNTIF(data!C$2:C$6155,CONCATENATE(">",$A3))) -> 10 | F3: =SUM(COUNTIF(data!D$2:D$6155,CONCATENATE("=",$A2)),COUNTIF(data!D$2:D$6155,CONCATENATE(">",$A2))-COUNTIF(data!D$2:D$6155,CONCATENATE(">",$A3))) -> 1
A4: =A3+3 -> -84 | B4: =CONCATENATE(ROUND(A3,2),"-",ROUND(A4,2)) -> -87--84 | C4: =SUM(COUNTIF(data!A$2:A$6155,CONCATENATE("=",$A3)),COUNTIF(data!A$2:A$6155,CONCATENATE(">",$A3))-COUNTIF(data!A$2:A$6155,CONCATENATE(">",$A4))) -> 74 | D4: =SUM(COUNTIF(data!B$2:B$6155,CONCATENATE("=",$A3)),COUNTIF(data!B$2:B$6155,CONCATENATE(">",$A3))-COUNTIF(data!B$2:B$6155,CONCATENATE(">",$A4))) -> 5 | E4: =SUM(COUNTIF(data!C$2:C$6155,CONCATENATE("=",$A3)),COUNTIF(data!C$2:C$6155,CONCATENATE(">",$A3))-COUNTIF(data!C$2:C$6155,CONCATENATE(">",$A4))) -> 21 | F4: =SUM(COUNTIF(data!D$2:D$6155,CONCATENATE("=",$A3)),COUNTIF(data!D$2:D$6155,CONCATENATE(">",$A3))-COUNTIF(data!D$2:D$6155,CONCATENATE(">",$A4))) -> 5
A5: =A4+3 -> -81 | B5: =CONCATENATE(ROUND(A4,2),"-",ROUND(A5,2)) -> -84--81 | C5: =SUM(COUNTIF(data!A$2:A$6155,CONCATENATE("=",$A4)),COUNTIF(data!A$2:A$6155,CONCATENATE(">",$A4))-COUNTIF(data!A$2:A$6155,CONCATENATE(">",$A5))) -> 111 | D5: =SUM(COUNTIF(data!B$2:B$6155,CONCATENATE("=",$A4)),COUNTIF(data!B$2:B$6155,CONCATENATE(">",$A4))-COUNTIF(data!B$2:B$6155,CONCATENATE(">",$A5))) -> 1 | E5: =SUM(COUNTIF(data!C$2:C$6155,CONCATENATE("=",$A4)),COUNTIF(data!C$2:C$6155,CONCATENATE(">",$A4))-COUNTIF(data!C$2:C$6155,CONCATENATE(">",$A5))) -> 31 | F5: =SUM(COUNTIF(data!D$2:D$6155,CONCATENATE("=",$A4)),COUNTIF(data!D$2:D$6155,CONCATENATE(">",$A4))-COUNTIF(data!D$2:D$6155,CONCATENATE(">",$A5))) -> 2
A6: =A5+3 -> -78 | B6: =CONCATENATE(ROUND(A5,2),"-",ROUND(A6,2)) -> -81--78 | C6: =SUM(COUNTIF(data!A$2:A$6155,CONCATENATE("=",$A5)),COUNTIF(data!A$2:A$6155,CONCATENATE(">",$A5))-COUNTIF(data!A$2:A$6155,CONCATENATE(">",$A6))) -> 86 | D6: =SUM(COUNTIF(data!B$2:B$6155,CONCATENATE("=",$A5)),COUNTIF(data!B$2:B$6155,CONCATENATE(">",$A5))-COUNTIF(data!B$2:B$6155,CONCATENATE(">",$A6))) -> 8 | E6: =SUM(COUNTIF(data!C$2:C$6155,CONCATENATE("=",$A5)),COUNTIF(data!C$2:C$6155,CONCATENATE(">",$A5))-COUNTIF(data!C$2:C$6155,CONCATENATE(">",$A6))) -> 49 | F6: =SUM(COUNTIF(data!D$2:D$6155,CONCATENATE("=",$A5)),COUNTIF(data!D$2:D$6155,CONCATENATE(">",$A5))-COUNTIF(data!D$2:D$6155,CONCATENATE(">",$A6))) -> 7
A7: =A6+3 -> -75 | B7: =CONCATENATE(ROUND(A6,2),"-",ROUND(A7,2)) -> -78--75 | C7: =SUM(COUNTIF(data!A$2:A$6155,CONCATENATE("=",$A6)),COUNTIF(data!A$2:A$6155,CONCATENATE(">",$A6))-COUNTIF(data!A$2:A$6155,CONCATENATE(">",$A7))) -> 78 | D7: =SUM(COUNTIF(data!B$2:B$6155,CONCATENATE("=",$A6)),COUNTIF(data!B$2:B$6155,CONCATENATE(">",$A6))-COUNTIF(data!B$2:B$6155,CONCATENATE(">",$A7))) -> 2 | E7: =SUM(COUNTIF(data!C$2:C$6155,CONCATENATE("=",$A6)),COUNTIF(data!C$2:C$6155,CONCATENATE(">",$A6))-COUNTIF(data!C$2:C$6155,CONCATENATE(">",$A7))) -> 44 | F7: =SUM(COUNTIF(data!D$2:D$6155,CONCATENATE("=",$A6)),COUNTIF(data!D$2:D$6155,CONCATENATE(">",$A6))-COUNTIF(data!D$2:D$6155,CONCATENATE(">",$A7))) -> 9
A8: =A7+3 -> -72 | B8: =CONCATENATE(ROUND(A7,2),"-",ROUND(A8,2)) -> -75--72 | C8: =SUM(COUNTIF(data!A$2:A$6155,CONCATENATE("=",$A7)),COUNTIF(data!A$2:A$6155,CONCATENATE(">",$A7))-COUNTIF(data!A$2:A$6155,CONCATENATE(">",$A8))) -> 75 | D8: =SUM(COUNTIF(data!B$2:B$6155,CONCATENATE("=",$A7)),COUNTIF(data!B$2:B$6155,CONCATENATE(">",$A7))-COUNTIF(data!B$2:B$6155,CONCATENATE(">",$A8))) -> 11 | E8: =SUM(COUNTIF(data!C$2:C$6155,CONCATENATE("=",$A7)),COUNTIF(data!C$2:C$6155,CONCATENATE(">",$A7))-COUNTIF(data!C$2:C$6155,CONCATENATE(">",$A8))) -> 67 | F8: =SUM(COUNTIF(data!D$2:D$6155,CONCATENATE("=",$A7)),COUNTIF(data!D$2:D$6155,CONCATENATE(">",$A7))-COUNTIF(data!D$2:D$6155,CONCATENATE(">",$A8))) -> 7
A9: =A8+3 -> -69 | B9: =CONCATENATE(ROUND(A8,2),"-",ROUND(A9,2)) -> -72--69 | C9: =SUM(COUNTIF(data!A$2:A$6155,CONCATENATE("=",$A8)),COUNTIF(data!A$2:A$6155,CONCATENATE(">",$A8))-COUNTIF(data!A$2:A$6155,CONCATENATE(">",$A9))) -> 84 | D9: =SUM(COUNTIF(data!B$2:B$6155,CONCATENATE("=",$A8)),COUNTIF(data!B$2:B$6155,CONCATENATE(">",$A8))-COUNTIF(data!B$2:B$6155,CONCATENATE(">",$A9))) -> 11 | E9: =SUM(COUNTIF(data!C$2:C$6155,CONCATENATE("=",$A8)),COUNTIF(data!C$2:C$6155,CONCATENATE(">",$A8))-COUNTIF(data!C$2:C$6155,CONCATENATE(">",$A9))) -> 56 | F9: =SUM(COUNTIF(data!D$2:D$6155,CONCATENATE("=",$A8)),COUNTIF(data!D$2:D$6155,CONCATENATE(">",$A8))-COUNTIF(data!D$2:D$6155,CONCATENATE(">",$A9))) -> 6
A10: =A9+3 -> -66 | B10: =CONCATENATE(ROUND(A9,2),"-",ROUND(A10,2)) -> -69--66 | C10: =SUM(COUNTIF(data!A$2:A$6155,CONCATENATE("=",$A9)),COUNTIF(data!A$2:A$6155,CONCATENATE(">",$A9))-COUNTIF(data!A$2:A$6155,CONCATENATE(">",$A10))) -> 73 | D10: =SUM(COUNTIF(data!B$2:B$6155,CONCATENATE("=",$A9)),COUNTIF(data!B$2:B$6155,CONCATENATE(">",$A9))-COUNTIF(data!B$2:B$6155,CONCATENATE(">",$A10))) -> 12 | E10: =SUM(COUNTIF(data!C$2:C$6155,CONCATENATE("=",$A9)),COUNTIF(data!C$2:C$6155,CONCATENATE(">",$A9))-COUNTIF(data!C$2:C$6155,CONCATENATE(">",$A10))) -> 67 | F10: =SUM(COUNTIF(data!D$2:D$6155,CONCATENATE("=",$A9)),COUNTIF(data!D$2:D$6155,CONCATENATE(">",$A9))-COUNTIF(data!D$2:D$6155,CONCATENATE(">",$A10))) -> 8
A11: =A10+3 -> -63 | B11: =CONCATENATE(ROUND(A10,2),"-",ROUND(A11,2)) -> -66--63 | C11: =SUM(COUNTIF(data!A$2:A$6155,CONCATENATE("=",$A10)),COUNTIF(data!A$2:A$6155,CONCATENATE(">",$A10))-COUNTIF(data!A$2:A$6155,CONCATENATE(">",$A11))) -> 74 | D11: =SUM(COUNTIF(data!B$2:B$6155,CONCATENATE("=",$A10)),COUNTIF(data!B$2:B$6155,CONCATENATE(">",$A10))-COUNTIF(data!B$2:B$6155,CONCATENATE(">",$A11))) -> 12 | E11: =SUM(COUNTIF(data!C$2:C$6155,CONCATENATE("=",$A10)),COUNTIF(data!C$2:C$6155,CONCATENATE(">",$A10))-COUNTIF(data!C$2:C$6155,CONCATENATE(">",$A11))) -> 77 | F11: =SUM(COUNTIF(data!D$2:D$6155,CONCATENATE("=",$A10)),COUNTIF(data!D$2:D$6155,CONCATENATE(">",$A10))-COUNTIF(data!D$2:D$6155,CONCATENATE(">",$A11))) -> 10
A12: =A11+3 -> -60 | B12: =CONCATENATE(ROUND(A11,2),"-",ROUND(A12,2)) -> -63--60 | C12: =SUM(COUNTIF(data!A$2:A$6155,CONCATENATE("=",$A11)),COUNTIF(data!A$2:A$6155,CONCATENATE(">",$A11))-COUNTIF(data!A$2:A$6155,CONCATENATE(">",$A12))) -> 64 | D12: =SUM(COUNTIF(data!B$2:B$6155,CONCATENATE("=",$A11)),COUNTIF(data!B$2:B$6155,CONCATENATE(">",$A11))-COUNTIF(data!B$2:B$6155,CONCATENATE(">",$A12))) -> 16 | E12: =SUM(COUNTIF(data!C$2:C$6155,CONCATENATE("=",$A11)),COUNTIF(data!C$2:C$6155,CONCATENATE(">",$A11))-COUNTIF(data!C$2:C$6155,CONCATENATE(">",$A12))) -> 67 | F12: =SUM(COUNTIF(data!D$2:D$6155,CONCATENATE("=",$A11)),COUNTIF(data!D$2:D$6155,CONCATENATE(">",$A11))-COUNTIF(data!D$2:D$6155,CONCATENATE(">",$A12))) -> 7
A13: =A12+3 -> -57 | B13: =CONCATENATE(ROUND(A12,2),"-",ROUND(A13,2)) -> -60--57 | C13: =SUM(COUNTIF(data!A$2:A$6155,CONCATENATE("=",$A12)),COUNTIF(data!A$2:A$6155,CONCATENATE(">",$A12))-COUNTIF(data!A$2:A$6155,CONCATENATE(">",$A13))) -> 85 | D13: =SUM(COUNTIF(data!B$2:B$6155,CONCATENATE("=",$A12)),COUNTIF(data!B$2:B$6155,CONCATENATE(">",$A12))-COUNTIF(data!B$2:B$6155,CONCATENATE(">",$A13))) -> 16 | E13: =SUM(COUNTIF(data!C$2:C$6155,CONCATENATE("=",$A12)),COUNTIF(data!C$2:C$6155,CONCATENATE(">",$A12))-COUNTIF(data!C$2:C$6155,CONCATENATE(">",$A13))) -> 98 | F13: =SUM(COUNTIF(data!D$2:D$6155,CONCATENATE("=",$A12)),COUNTIF(data!D$2:D$6155,CONCATENATE(">",$A12))-COUNTIF(data!D$2:D$6155,CONCATENATE(">",$A13))) -> 14
A14: =A13+3 -> -54 | B14: =CONCATENATE(ROUND(A13,2),"-",ROUND(A14,2)) -> -57--54 | C14: =SUM(COUNTIF(data!A$2:A$6155,CONCATENATE("=",$A13)),COUNTIF(data!A$2:A$6155,CONCATENATE(">",$A13))-COUNTIF(data!A$2:A$6155,CONCATENATE(">",$A14))) -> 66 | D14: =SUM(COUNTIF(data!B$2:B$6155,CONCATENATE("=",$A13)),COUNTIF(data!B$2:B$6155,CONCATENATE(">",$A13))-COUNTIF(data!B$2:B$6155,CONCATENATE(">",$A14))) -> 20 | E14: =SUM(COUNTIF(data!C$2:C$6155,CONCATENATE("=",$A13)),COUNTIF(data!C$2:C$6155,CONCATENATE(">",$A13))-COUNTIF(data!C$2:C$6155,CONCATENATE(">",$A14))) -> 87 | F14: =SUM(COUNTIF(data!D$2:D$6155,CONCATENATE("=",$A13)),COUNTIF(data!D$2:D$6155,CONCATENATE(">",$A13))-COUNTIF(data!D$2:D$6155,CONCATENATE(">",$A14))) -> 13
... A62: =A61+3 -> 90 | B62: =CONCATENATE(ROUND(A61,2),"-",ROUND(A62,2)) -> 87-90 | C62: =SUM(COUNTIF(data!A$2:A$6155,CONCATENATE("=",$A61)),COUNTIF(data!A$2:A$6155,CONCATENATE(">",$A61))-COUNTIF(data!A$2:A$6155,CONCATENATE(">",$A62))) -> 17 | D62: =SUM(COUNTIF(data!B$2:B$6155,CONCATENATE("=",$A61)),COUNTIF(data!B$2:B$6155,CONCATENATE(">",$A61))-COUNTIF(data!B$2:B$6155,CONCATENATE(">",$A62))) -> 3 | E62: =SUM(COUNTIF(data!C$2:C$6155,CONCATENATE("=",$A61)),COUNTIF(data!C$2:C$6155,CONCATENATE(">",$A61))-COUNTIF(data!C$2:C$6155,CONCATENATE(">",$A62))) -> 7 | F62: =SUM(COUNTIF(data!D$2:D$6155,CONCATENATE("=",$A61)),COUNTIF(data!D$2:D$6155,CONCATENATE(">",$A61))-COUNTIF(data!D$2:D$6155,CONCATENATE(">",$A62))) -> 0
