Workbook

Sheet data
A1: CellProfiler | B1: FAST | C1: SuperSegger | D1: Oufti
A2: -0.12 | B2: 0.13563984 | C2: 0.011757455 | D2: -0.048
A3: -0.28 | B3: 0.21463346 | C3: 0.11791094 | D3: 0.132
A4: 0.134 | B4: -0.032740964 | C4: 0.29897541 | D4: -0.337
A5: 0.396 | B5: 0.63304065 | C5: 0.0032707883 | D5: 0.081
A6: -0.063 | B6: 0.07968444 | C6: -0.040543226 | D6: 0.377
A7: 1.237 | B7: -0.054825362 | C7: 0.022186599 | D7: -1.013
A8: 0.205 | B8: -0.089470869 | C8: 0.036091943 | D8: 0.111
A9: 0.13 | B9: 0.0024932705 | C9: 0.0030406707 | D9: -0.795
A10: 0.254 | B10: 0.02177781 | C10: -0.1160659 | D10: 0.133
A11: 0.212 | B11: -0.18408259 | C11: -0.023233559 | D11: -0.62
A12: 0.147 | B12: -0.12761707 | C12: 0.048993986 | D12: -0.384
A13: 0.03 | B13: -0.032307009 | C13: -0.14575158 | D13: -0.503
... A274: -1.503 | B274: 0.0052131533 | C274: 0.057740062 | D274: 0.626
A275: -0.011 | B275: -0.21894018 | C275: 0.13432738
A276: 0.162 | B276: -0.71677426 | C276: 0.10892701
A277: 0.109 | B277: 0.098787928 | C277: -0.075317639
A278: -0.167 | B278: -0.21689451 | C278: 0.1423603
A279: -0.19 | B279: -0.14532387 | C279: 0.46925841
A280: 0.702 | B280: 0.21317512 | C280: 0.0086490993
A281: 0.669 | B281: 1.7391466 | C281: -0.12459205
A282: 0.173 | B282: 0.05866001 | C282: 0.048073403
A283: 0.402 | B283: -0.13719407 | C283: -0.26211125
A284: -0.027 | B284: 0.12144137 | C284: -0.44427877
A285: 0.148 | B285: -0.13051519 | C285: 0.35177427
A286: 0.038 | B286: -0.10627527 | C286: 0.16002097
... A1193: 1.398 | B1193: 0.26216053 | C1193: -0.47634441
A1194: 0.477 | C1194: 0.058341387
A1195: -0.676 | C1195: -0.59803651
A1196: -1.304 | C1196: -0.048487275
A1197: -0.461 | C1197: 1.2479657
A1198: 0.862 | C1198: 0.2931769
A1199: 0.461 | C1199: 0.45803255
A1200: -0.517 | C1200: 0.89706728
A1201: 0.081 | C1201: 0.47764177
A1202: 0.956 | C1202: 0.31862922
A1203: -0.006 | C1203: 1.1845029
A1204: 1.563 | C1204: 0.12500606
A1205: 1.695 | C1205: 0.63906393
... A4621: 0.219 | C4621: -1.0498585
...

Sheet plot
A1: Bins | B1: Lable | C1: CellProfiler | D1: FAST | E1: SuperSegger | F1: Oufti
A2: =MIN(data!A2:D6155) -> -15.554251 | B2: =MAX(data!A2:D6155) -> 53.757839
A3: =A2+1.5 -> -14.054251 | B3: =CONCATENATE(ROUND(A2,2),"-",ROUND(A3,2)) -> -15.55--14.05 | C3: =SUM(COUNTIF(data!A$2:A$6155,CONCATENATE("=",$A2)),COUNTIF(data!A$2:A$6155,CONCATENATE(">",$A2))-COUNTIF(data!A$2:A$6155,CONCATENATE(">",$A3))) -> 0 | D3: =SUM(COUNTIF(data!B$2:B$6155,CONCATENATE("=",$A2)),COUNTIF(data!B$2:B$6155,CONCATENATE(">",$A2))-COUNTIF(data!B$2:B$6155,CONCATENATE(">",$A3))) -> 0 | E3: =SUM(COUNTIF(data!C$2:C$6155,CONCATENATE("=",$A2)),COUNTIF(data!C$2:C$6155,CONCATENATE(">",$A2))-COUNTIF(data!C$2:C$6155,CONCATENATE(">",$A3))) -> 1 | F3: =SUM(COUNTIF(data!D$2:D$6155,CONCATENATE("=",$A2)),COUNTIF(data!D$2:D$6155,CONCATENATE(">",$A2))-COUNTIF(data!D$2:D$6155,CONCATENATE(">",$A3))) -> 0
A4: =A3+1.5 -> -12.554251 | B4: =CONCATENATE(ROUND(A3,2),"-",ROUND(A4,2)) -> -14.05--12.55 | C4: =SUM(COUNTIF(data!A$2:A$6155,CONCATENATE("=",$A3)),COUNTIF(data!A$2:A$6155,CONCATENATE(">",$A3))-COUNTIF(data!A$2:A$6155,CONCATENATE(">",$A4))) -> 0 | D4: =SUM(COUNTIF(data!B$2:B$6155,CONCATENATE("=",$A3)),COUNTIF(data!B$2:B$6155,CONCATENATE(">",$A3))-COUNTIF(data!B$2:B$6155,CONCATENATE(">",$A4))) -> 0 | E4: =SUM(COUNTIF(data!C$2:C$6155,CONCATENATE("=",$A3)),COUNTIF(data!C$2:C$6155,CONCATENATE(">",$A3))-COUNTIF(data!C$2:C$6155,CONCATENATE(">",$A4))) -> 0 | F4: =SUM(COUNTIF(data!D$2:D$6155,CONCATENATE("=",$A3)),COUNTIF(data!D$2:D$6155,CONCATENATE(">",$A3))-COUNTIF(data!D$2:D$6155,CONCATENATE(">",$A4))) -> 0
A5: =A4+1.5 -> -11.054251 | B5: =CONCATENATE(ROUND(A4,2),"-",ROUND(A5,2)) -> -12.55--11.05 | C5: =SUM(COUNTIF(data!A$2:A$6155,CONCATENATE("=",$A4)),COUNTIF(data!A$2:A$6155,CONCATENATE(">",$A4))-COUNTIF(data!A$2:A$6155,CONCATENATE(">",$A5))) -> 0 | D5: =SUM(COUNTIF(data!B$2:B$6155,CONCATENATE("=",$A4)),COUNTIF(data!B$2:B$6155,CONCATENATE(">",$A4))-COUNTIF(data!B$2:B$6155,CONCATENATE(">",$A5))) -> 0 | E5: =SUM(COUNTIF(data!C$2:C$6155,CONCATENATE("=",$A4)),COUNTIF(data!C$2:C$6155,CONCATENATE(">",$A4))-COUNTIF(data!C$2:C$6155,CONCATENATE(">",$A5))) -> 0 | F5: =SUM(COUNTIF(data!D$2:D$6155,CONCATENATE("=",$A4)),COUNTIF(data!D$2:D$6155,CONCATENATE(">",$A4))-COUNTIF(data!D$2:D$6155,CONCATENATE(">",$A5))) -> 0
A6: =A5+1.5 -> -9.5542513 | B6: =CONCATENATE(ROUND(A5,2),"-",ROUND(A6,2)) -> -11.05--9.55 | C6: =SUM(COUNTIF(data!A$2:A$6155,CONCATENATE("=",$A5)),COUNTIF(data!A$2:A$6155,CONCATENATE(">",$A5))-COUNTIF(data!A$2:A$6155,CONCATENATE(">",$A6))) -> 0 | D6: =SUM(COUNTIF(data!B$2:B$6155,CONCATENATE("=",$A5)),COUNTIF(data!B$2:B$6155,CONCATENATE(">",$A5))-COUNTIF(data!B$2:B$6155,CONCATENATE(">",$A6))) -> 0 | E6: =SUM(COUNTIF(data!C$2:C$6155,CONCATENATE("=",$A5)),COUNTIF(data!C$2:C$6155,CONCATENATE(">",$A5))-COUNTIF(data!C$2:C$6155,CONCATENATE(">",$A6))) -> 0 | F6: =SUM(COUNTIF(data!D$2:D$6155,CONCATENATE("=",$A5)),COUNTIF(data!D$2:D$6155,CONCATENATE(">",$A5))-COUNTIF(data!D$2:D$6155,CONCATENATE(">",$A6))) -> 0
A7: =A6+1.5 -> -8.0542513 | B7: =CONCATENATE(ROUND(A6,2),"-",ROUND(A7,2)) -> -9.55--8.05 | C7: =SUM(COUNTIF(data!A$2:A$6155,CONCATENATE("=",$A6)),COUNTIF(data!A$2:A$6155,CONCATENATE(">",$A6))-COUNTIF(data!A$2:A$6155,CONCATENATE(">",$A7))) -> 0 | D7: =SUM(COUNTIF(data!B$2:B$6155,CONCATENATE("=",$A6)),COUNTIF(data!B$2:B$6155,CONCATENATE(">",$A6))-COUNTIF(data!B$2:B$6155,CONCATENATE(">",$A7))) -> 0 | E7: =SUM(COUNTIF(data!C$2:C$6155,CONCATENATE("=",$A6)),COUNTIF(data!C$2:C$6155,CONCATENATE(">",$A6))-COUNTIF(data!C$2:C$6155,CONCATENATE(">",$A7))) -> 0 | F7: =SUM(COUNTIF(data!D$2:D$6155,CONCATENATE("=",$A6)),COUNTIF(data!D$2:D$6155,CONCATENATE(">",$A6))-COUNTIF(data!D$2:D$6155,CONCATENATE(">",$A7))) -> 0
A8: =A7+1.5 -> -6.5542513 | B8: =CONCATENATE(ROUND(A7,2),"-",ROUND(A8,2)) -> -8.05--6.55 | C8: =SUM(COUNTIF(data!A$2:A$6155,CONCATENATE("=",$A7)),COUNTIF(data!A$2:A$6155,CONCATENATE(">",$A7))-COUNTIF(data!A$2:A$6155,CONCATENATE(">",$A8))) -> 0 | D8: =SUM(COUNTIF(data!B$2:B$6155,CONCATENATE("=",$A7)),COUNTIF(data!B$2:B$6155,CONCATENATE(">",$A7))-COUNTIF(data!B$2:B$6155,CONCATENATE(">",$A8))) -> 0 | E8: =SUM(COUNTIF(data!C$2:C$6155,CONCATENATE("=",$A7)),COUNTIF(data!C$2:C$6155,CONCATENATE(">",$A7))-COUNTIF(data!C$2:C$6155,CONCATENATE(">",$A8))) -> 0 | F8: =SUM(COUNTIF(data!D$2:D$6155,CONCATENATE("=",$A7)),COUNTIF(data!D$2:D$6155,CONCATENATE(">",$A7))-COUNTIF(data!D$2:D$6155,CONCATENATE(">",$A8))) -> 0
A9: =A8+1.5 -> -5.0542513 | B9: =CONCATENATE(ROUND(A8,2),"-",ROUND(A9,2)) -> -6.55--5.05 | C9: =SUM(COUNTIF(data!A$2:A$6155,CONCATENATE("=",$A8)),COUNTIF(data!A$2:A$6155,CONCATENATE(">",$A8))-COUNTIF(data!A$2:A$6155,CONCATENATE(">",$A9))) -> 2 | D9: =SUM(COUNTIF(data!B$2:B$6155,CONCATENATE("=",$A8)),COUNTIF(data!B$2:B$6155,CONCATENATE(">",$A8))-COUNTIF(data!B$2:B$6155,CONCATENATE(">",$A9))) -> 0 | E9: =SUM(COUNTIF(data!C$2:C$6155,CONCATENATE("=",$A8)),COUNTIF(data!C$2:C$6155,CONCATENATE(">",$A8))-COUNTIF(data!C$2:C$6155,CONCATENATE(">",$A9))) -> 0 | F9: =SUM(COUNTIF(data!D$2:D$6155,CONCATENATE("=",$A8)),COUNTIF(data!D$2:D$6155,CONCATENATE(">",$A8))-COUNTIF(data!D$2:D$6155,CONCATENATE(">",$A9))) -> 0
A10: =A9+1.5 -> -3.5542513 | B10: =CONCATENATE(ROUND(A9,2),"-",ROUND(A10,2)) -> -5.05--3.55 | C10: =SUM(COUNTIF(data!A$2:A$6155,CONCATENATE("=",$A9)),COUNTIF(data!A$2:A$6155,CONCATENATE(">",$A9))-COUNTIF(data!A$2:A$6155,CONCATENATE(">",$A10))) -> 11 | D10: =SUM(COUNTIF(data!B$2:B$6155,CONCATENATE("=",$A9)),COUNTIF(data!B$2:B$6155,CONCATENATE(">",$A9))-COUNTIF(data!B$2:B$6155,CONCATENATE(">",$A10))) -> 0 | E10: =SUM(COUNTIF(data!C$2:C$6155,CONCATENATE("=",$A9)),COUNTIF(data!C$2:C$6155,CONCATENATE(">",$A9))-COUNTIF(data!C$2:C$6155,CONCATENATE(">",$A10))) -> 7 | F10: =SUM(COUNTIF(data!D$2:D$6155,CONCATENATE("=",$A9)),COUNTIF(data!D$2:D$6155,CONCATENATE(">",$A9))-COUNTIF(data!D$2:D$6155,CONCATENATE(">",$A10))) -> 0
A11: =A10+1.5 -> -2.0542513 | B11: =CONCATENATE(ROUND(A10,2),"-",ROUND(A11,2)) -> -3.55--2.05 | C11: =SUM(COUNTIF(data!A$2:A$6155,CONCATENATE("=",$A10)),COUNTIF(data!A$2:A$6155,CONCATENATE(">",$A10))-COUNTIF(data!A$2:A$6155,CONCATENATE(">",$A11))) -> 57 | D11: =SUM(COUNTIF(data!B$2:B$6155,CONCATENATE("=",$A10)),COUNTIF(data!B$2:B$6155,CONCATENATE(">",$A10))-COUNTIF(data!B$2:B$6155,CONCATENATE(">",$A11))) -> 6 | E11: =SUM(COUNTIF(data!C$2:C$6155,CONCATENATE("=",$A10)),COUNTIF(data!C$2:C$6155,CONCATENATE(">",$A10))-COUNTIF(data!C$2:C$6155,CONCATENATE(">",$A11))) -> 26 | F11: =SUM(COUNTIF(data!D$2:D$6155,CONCATENATE("=",$A10)),COUNTIF(data!D$2:D$6155,CONCATENATE(">",$A10))-COUNTIF(data!D$2:D$6155,CONCATENATE(">",$A11))) -> 2
A12: =A11+1.5 -> -0.55425129 | B12: =CONCATENATE(ROUND(A11,2),"-",ROUND(A12,2)) -> -2.05--0.55 | C12: =SUM(COUNTIF(data!A$2:A$6155,CONCATENATE("=",$A11)),COUNTIF(data!A$2:A$6155,CONCATENATE(">",$A11))-COUNTIF(data!A$2:A$6155,CONCATENATE(">",$A12))) -> 721 | D12: =SUM(COUNTIF(data!B$2:B$6155,CONCATENATE("=",$A11)),COUNTIF(data!B$2:B$6155,CONCATENATE(">",$A11))-COUNTIF(data!B$2:B$6155,CONCATENATE(">",$A12))) -> 212 | E12: =SUM(COUNTIF(data!C$2:C$6155,CONCATENATE("=",$A11)),COUNTIF(data!C$2:C$6155,CONCATENATE(">",$A11))-COUNTIF(data!C$2:C$6155,CONCATENATE(">",$A12))) -> 784 | F12: =SUM(COUNTIF(data!D$2:D$6155,CONCATENATE("=",$A11)),COUNTIF(data!D$2:D$6155,CONCATENATE(">",$A11))-COUNTIF(data!D$2:D$6155,CONCATENATE(">",$A12))) -> 70
A13: =A12+1.5 -> 0.94574871 | B13: =CONCATENATE(ROUND(A12,2),"-",ROUND(A13,2)) -> -0.55-0.95 | C13: =SUM(COUNTIF(data!A$2:A$6155,CONCATENATE("=",$A12)),COUNTIF(data!A$2:A$6155,CONCATENATE(">",$A12))-COUNTIF(data!A$2:A$6155,CONCATENATE(">",$A13))) -> 3446 | D13: =SUM(COUNTIF(data!B$2:B$6155,CONCATENATE("=",$A12)),COUNTIF(data!B$2:B$6155,CONCATENATE(">",$A12))-COUNTIF(data!B$2:B$6155,CONCATENATE(">",$A13))) -> 921 | E13: =SUM(COUNTIF(data!C$2:C$6155,CONCATENATE("=",$A12)),COUNTIF(data!C$2:C$6155,CONCATENATE(">",$A12))-COUNTIF(data!C$2:C$6155,CONCATENATE(">",$A13))) -> 4940 | F13: =SUM(COUNTIF(data!D$2:D$6155,CONCATENATE("=",$A12)),COUNTIF(data!D$2:D$6155,CONCATENATE(">",$A12))-COUNTIF(data!D$2:D$6155,CONCATENATE(">",$A13))) -> 199
A14: =A13+1.5 -> 2.4457487 | B14: =CONCATENATE(ROUND(A13,2),"-",ROUND(A14,2)) -> 0.95-2.45 | C14: =SUM(COUNTIF(data!A$2:A$6155,CONCATENATE("=",$A13)),COUNTIF(data!A$2:A$6155,CONCATENATE(">",$A13))-COUNTIF(data!A$2:A$6155,CONCATENATE(">",$A14))) -> 336 | D14: =SUM(COUNTIF(data!B$2:B$6155,CONCATENATE("=",$A13)),COUNTIF(data!B$2:B$6155,CONCATENATE(">",$A13))-COUNTIF(data!B$2:B$6155,CONCATENATE(">",$A14))) -> 52 | E14: =SUM(COUNTIF(data!C$2:C$6155,CONCATENATE("=",$A13)),COUNTIF(data!C$2:C$6155,CONCATENATE(">",$A13))-COUNTIF(data!C$2:C$6155,CONCATENATE(">",$A14))) -> 369 | F14: =SUM(COUNTIF(data!D$2:D$6155,CONCATENATE("=",$A13)),COUNTIF(data!D$2:D$6155,CONCATENATE(">",$A13))-COUNTIF(data!D$2:D$6155,CONCATENATE(">",$A14))) -> 2
... A49: =A48+1.5 -> 54.945749 | B49: =CONCATENATE(ROUND(A48,2),"-",ROUND(A49,2)) -> 53.45-54.95 | C49: =SUM(COUNTIF(data!A$2:A$6155,CONCATENATE("=",$A48)),COUNTIF(data!A$2:A$6155,CONCATENATE(">",$A48))-COUNTIF(data!A$2:A$6155,CONCATENATE(">",$A49))) -> 0 | D49: =SUM(COUNTIF(data!B$2:B$6155,CONCATENATE("=",$A48)),COUNTIF(data!B$2:B$6155,CONCATENATE(">",$A48))-COUNTIF(data!B$2:B$6155,CONCATENATE(">",$A49))) -> 0 | E49: =SUM(COUNTIF(data!C$2:C$6155,CONCATENATE("=",$A48)),COUNTIF(data!C$2:C$6155,CONCATENATE(">",$A48))-COUNTIF(data!C$2:C$6155,CONCATENATE(">",$A49))) -> 1 | F49: =SUM(COUNTIF(data!D$2:D$6155,CONCATENATE("=",$A48)),COUNTIF(data!D$2:D$6155,CONCATENATE(">",$A48))-COUNTIF(data!D$2:D$6155,CONCATENATE(">",$A49))) -> 0

Sheet zoom in
A1: Bins | B1: Lable | C1: CellProfiler | D1: FAST | E1: SuperSegger | F1: Oufti
A2: =-3 -> -3 | B2: =MAX(data!A2:D6155) -> 53.757839
A3: =A2+0.2 -> -2.8 | B3: =CONCATENATE(ROUND(A2,2),"-",ROUND(A3,2)) -> -3--2.8 | C3: =SUM(COUNTIF(data!A$2:A$6155,CONCATENATE("=",$A2)),COUNTIF(data!A$2:A$6155,CONCATENATE(">",$A2))-COUNTIF(data!A$2:A$6155,CONCATENATE(">",$A3))) -> 7 | D3: =SUM(COUNTIF(data!B$2:B$6155,CONCATENATE("=",$A2)),COUNTIF(data!B$2:B$6155,CONCATENATE(">",$A2))-COUNTIF(data!B$2:B$6155,CONCATENATE(">",$A3))) -> 1 | E3: =SUM(COUNTIF(data!C$2:C$6155,CONCATENATE("=",$A2)),COUNTIF(data!C$2:C$6155,CONCATENATE(">",$A2))-COUNTIF(data!C$2:C$6155,CONCATENATE(">",$A3))) -> 2 | F3: =SUM(COUNTIF(data!D$2:D$6155,CONCATENATE("=",$A2)),COUNTIF(data!D$2:D$6155,CONCATENATE(">",$A2))-COUNTIF(data!D$2:D$6155,CONCATENATE(">",$A3))) -> 0
A4: =A3+0.2 -> -2.6 | B4: =CONCATENATE(ROUND(A3,2),"-",ROUND(A4,2)) -> -2.8--2.6 | C4: =SUM(COUNTIF(data!A$2:A$6155,CONCATENATE("=",$A3)),COUNTIF(data!A$2:A$6155,CONCATENATE(">",$A3))-COUNTIF(data!A$2:A$6155,CONCATENATE(">",$A4))) -> 4 | D4: =SUM(COUNTIF(data!B$2:B$6155,CONCATENATE("=",$A3)),COUNTIF(data!B$2:B$6155,CONCATENATE(">",$A3))-COUNTIF(data!B$2:B$6155,CONCATENATE(">",$A4))) -> 0 | E4: =SUM(COUNTIF(data!C$2:C$6155,CONCATENATE("=",$A3)),COUNTIF(data!C$2:C$6155,CONCATENATE(">",$A3))-COUNTIF(data!C$2:C$6155,CONCATENATE(">",$A4))) -> 7 | F4: =SUM(COUNTIF(data!D$2:D$6155,CONCATENATE("=",$A3)),COUNTIF(data!D$2:D$6155,CONCATENATE(">",$A3))-COUNTIF(data!D$2:D$6155,CONCATENATE(">",$A4))) -> 0
A5: =A4+0.2 -> -2.4 | B5: =CONCATENATE(ROUND(A4,2),"-",ROUND(A5,2)) -> -2.6--2.4 | C5: =SUM(COUNTIF(data!A$2:A$6155,CONCATENATE("=",$A4)),COUNTIF(data!A$2:A$6155,CONCATENATE(">",$A4))-COUNTIF(data!A$2:A$6155,CONCATENATE(">",$A5))) -> 17 | D5: =SUM(COUNTIF(data!B$2:B$6155,CONCATENATE("=",$A4)),COUNTIF(data!B$2:B$6155,CONCATENATE(">",$A4))-COUNTIF(data!B$2:B$6155,CONCATENATE(">",$A5))) -> 0 | E5: =SUM(COUNTIF(data!C$2:C$6155,CONCATENATE("=",$A4)),COUNTIF(data!C$2:C$6155,CONCATENATE(">",$A4))-COUNTIF(data!C$2:C$6155,CONCATENATE(">",$A5))) -> 5 | F5: =SUM(COUNTIF(data!D$2:D$6155,CONCATENATE("=",$A4)),COUNTIF(data!D$2:D$6155,CONCATENATE(">",$A4))-COUNTIF(data!D$2:D$6155,CONCATENATE(">",$A5))) -> 0
A6: =A5+0.2 -> -2.2 | B6: =CONCATENATE(ROUND(A5,2),"-",ROUND(A6,2)) -> -2.4--2.2 | C6: =SUM(COUNTIF(data!A$2:A$6155,CONCATENATE("=",$A5)),COUNTIF(data!A$2:A$6155,CONCATENATE(">",$A5))-COUNTIF(data!A$2:A$6155,CONCATENATE(">",$A6))) -> 10 | D6: =SUM(COUNTIF(data!B$2:B$6155,CONCATENATE("=",$A5)),COUNTIF(data!B$2:B$6155,CONCATENATE(">",$A5))-COUNTIF(data!B$2:B$6155,CONCATENATE(">",$A6))) -> 2 | E6: =SUM(COUNTIF(data!C$2:C$6155,CONCATENATE("=",$A5)),COUNTIF(data!C$2:C$6155,CONCATENATE(">",$A5))-COUNTIF(data!C$2:C$6155,CONCATENATE(">",$A6))) -> 6 | F6: =SUM(COUNTIF(data!D$2:D$6155,CONCATENATE("=",$A5)),COUNTIF(data!D$2:D$6155,CONCATENATE(">",$A5))-COUNTIF(data!D$2:D$6155,CONCATENATE(">",$A6))) -> 2
A7: =A6+0.2 -> -2 | B7: =CONCATENATE(ROUND(A6,2),"-",ROUND(A7,2)) -> -2.2--2 | C7: =SUM(COUNTIF(data!A$2:A$6155,CONCATENATE("=",$A6)),COUNTIF(data!A$2:A$6155,CONCATENATE(">",$A6))-COUNTIF(data!A$2:A$6155,CONCATENATE(">",$A7))) -> 14 | D7: =SUM(COUNTIF(data!B$2:B$6155,CONCATENATE("=",$A6)),COUNTIF(data!B$2:B$6155,CONCATENATE(">",$A6))-COUNTIF(data!B$2:B$6155,CONCATENATE(">",$A7))) -> 4 | E7: =SUM(COUNTIF(data!C$2:C$6155,CONCATENATE("=",$A6)),COUNTIF(data!C$2:C$6155,CONCATENATE(">",$A6))-COUNTIF(data!C$2:C$6155,CONCATENATE(">",$A7))) -> 9 | F7: =SUM(COUNTIF(data!D$2:D$6155,CONCATENATE("=",$A6)),COUNTIF(data!D$2:D$6155,CONCATENATE(">",$A6))-COUNTIF(data!D$2:D$6155,CONCATENATE(">",$A7))) -> 1
A8: =A7+0.2 -> -1.8 | B8: =CONCATENATE(ROUND(A7,2),"-",ROUND(A8,2)) -> -2--1.8 | C8: =SUM(COUNTIF(data!A$2:A$6155,CONCATENATE("=",$A7)),COUNTIF(data!A$2:A$6155,CONCATENATE(">",$A7))-COUNTIF(data!A$2:A$6155,CONCATENATE(">",$A8))) -> 26 | D8: =SUM(COUNTIF(data!B$2:B$6155,CONCATENATE("=",$A7)),COUNTIF(data!B$2:B$6155,CONCATENATE(">",$A7))-COUNTIF(data!B$2:B$6155,CONCATENATE(">",$A8))) -> 6 | E8: =SUM(COUNTIF(data!C$2:C$6155,CONCATENATE("=",$A7)),COUNTIF(data!C$2:C$6155,CONCATENATE(">",$A7))-COUNTIF(data!C$2:C$6155,CONCATENATE(">",$A8))) -> 24 | F8: =SUM(COUNTIF(data!D$2:D$6155,CONCATENATE("=",$A7)),COUNTIF(data!D$2:D$6155,CONCATENATE(">",$A7))-COUNTIF(data!D$2:D$6155,CONCATENATE(">",$A8))) -> 1
A9: =A8+0.2 -> -1.6 | B9: =CONCATENATE(ROUND(A8,2),"-",ROUND(A9,2)) -> -1.8--1.6 | C9: =SUM(COUNTIF(data!A$2:A$6155,CONCATENATE("=",$A8)),COUNTIF(data!A$2:A$6155,CONCATENATE(">",$A8))-COUNTIF(data!A$2:A$6155,CONCATENATE(">",$A9))) -> 30 | D9: =SUM(COUNTIF(data!B$2:B$6155,CONCATENATE("=",$A8)),COUNTIF(data!B$2:B$6155,CONCATENATE(">",$A8))-COUNTIF(data!B$2:B$6155,CONCATENATE(">",$A9))) -> 6 | E9: =SUM(COUNTIF(data!C$2:C$6155,CONCATENATE("=",$A8)),COUNTIF(data!C$2:C$6155,CONCATENATE(">",$A8))-COUNTIF(data!C$2:C$6155,CONCATENATE(">",$A9))) -> 21 | F9: =SUM(COUNTIF(data!D$2:D$6155,CONCATENATE("=",$A8)),COUNTIF(data!D$2:D$6155,CONCATENATE(">",$A8))-COUNTIF(data!D$2:D$6155,CONCATENATE(">",$A9))) -> 7
A10: =A9+0.2 -> -1.4 | B10: =CONCATENATE(ROUND(A9,2),"-",ROUND(A10,2)) -> -1.6--1.4 | C10: =SUM(COUNTIF(data!A$2:A$6155,CONCATENATE("=",$A9)),COUNTIF(data!A$2:A$6155,CONCATENATE(">",$A9))-COUNTIF(data!A$2:A$6155,CONCATENATE(">",$A10))) -> 56 | D10: =SUM(COUNTIF(data!B$2:B$6155,CONCATENATE("=",$A9)),COUNTIF(data!B$2:B$6155,CONCATENATE(">",$A9))-COUNTIF(data!B$2:B$6155,CONCATENATE(">",$A10))) -> 13 | E10: =SUM(COUNTIF(data!C$2:C$6155,CONCATENATE("=",$A9)),COUNTIF(data!C$2:C$6155,CONCATENATE(">",$A9))-COUNTIF(data!C$2:C$6155,CONCATENATE(">",$A10))) -> 51 | F10: =SUM(COUNTIF(data!D$2:D$6155,CONCATENATE("=",$A9)),COUNTIF(data!D$2:D$6155,CONCATENATE(">",$A9))-COUNTIF(data!D$2:D$6155,CONCATENATE(">",$A10))) -> 5
A11: =A10+0.2 -> -1.2 | B11: =CONCATENATE(ROUND(A10,2),"-",ROUND(A11,2)) -> -1.4--1.2 | C11: =SUM(COUNTIF(data!A$2:A$6155,CONCATENATE("=",$A10)),COUNTIF(data!A$2:A$6155,CONCATENATE(">",$A10))-COUNTIF(data!A$2:A$6155,CONCATENATE(">",$A11))) -> 65 | D11: =SUM(COUNTIF(data!B$2:B$6155,CONCATENATE("=",$A10)),COUNTIF(data!B$2:B$6155,CONCATENATE(">",$A10))-COUNTIF(data!B$2:B$6155,CONCATENATE(">",$A11))) -> 19 | E11: =SUM(COUNTIF(data!C$2:C$6155,CONCATENATE("=",$A10)),COUNTIF(data!C$2:C$6155,CONCATENATE(">",$A10))-COUNTIF(data!C$2:C$6155,CONCATENATE(">",$A11))) -> 62 | F11: =SUM(COUNTIF(data!D$2:D$6155,CONCATENATE("=",$A10)),COUNTIF(data!D$2:D$6155,CONCATENATE(">",$A10))-COUNTIF(data!D$2:D$6155,CONCATENATE(">",$A11))) -> 3
A12: =A11+0.2 -> -1 | B12: =CONCATENATE(ROUND(A11,2),"-",ROUND(A12,2)) -> -1.2--1 | C12: =SUM(COUNTIF(data!A$2:A$6155,CONCATENATE("=",$A11)),COUNTIF(data!A$2:A$6155,CONCATENATE(">",$A11))-COUNTIF(data!A$2:A$6155,CONCATENATE(">",$A12))) -> 99 | D12: =SUM(COUNTIF(data!B$2:B$6155,CONCATENATE("=",$A11)),COUNTIF(data!B$2:B$6155,CONCATENATE(">",$A11))-COUNTIF(data!B$2:B$6155,CONCATENATE(">",$A12))) -> 25 | E12: =SUM(COUNTIF(data!C$2:C$6155,CONCATENATE("=",$A11)),COUNTIF(data!C$2:C$6155,CONCATENATE(">",$A11))-COUNTIF(data!C$2:C$6155,CONCATENATE(">",$A12))) -> 116 | F12: =SUM(COUNTIF(data!D$2:D$6155,CONCATENATE("=",$A11)),COUNTIF(data!D$2:D$6155,CONCATENATE(">",$A11))-COUNTIF(data!D$2:D$6155,CONCATENATE(">",$A12))) -> 10
A13: =A12+0.2 -> -0.8 | B13: =CONCATENATE(ROUND(A12,2),"-",ROUND(A13,2)) -> -1--0.8 | C13: =SUM(COUNTIF(data!A$2:A$6155,CONCATENATE("=",$A12)),COUNTIF(data!A$2:A$6155,CONCATENATE(">",$A12))-COUNTIF(data!A$2:A$6155,CONCATENATE(">",$A13))) -> 153 | D13: =SUM(COUNTIF(data!B$2:B$6155,CONCATENATE("=",$A12)),COUNTIF(data!B$2:B$6155,CONCATENATE(">",$A12))-COUNTIF(data!B$2:B$6155,CONCATENATE(">",$A13))) -> 55 | E13: =SUM(COUNTIF(data!C$2:C$6155,CONCATENATE("=",$A12)),COUNTIF(data!C$2:C$6155,CONCATENATE(">",$A12))-COUNTIF(data!C$2:C$6155,CONCATENATE(">",$A13))) -> 148 | F13: =SUM(COUNTIF(data!D$2:D$6155,CONCATENATE("=",$A12)),COUNTIF(data!D$2:D$6155,CONCATENATE(">",$A12))-COUNTIF(data!D$2:D$6155,CONCATENATE(">",$A13))) -> 12
A14: =A13+0.2 -> -0.6 | B14: =CONCATENATE(ROUND(A13,2),"-",ROUND(A14,2)) -> -0.8--0.6 | C14: =SUM(COUNTIF(data!A$2:A$6155,CONCATENATE("=",$A13)),COUNTIF(data!A$2:A$6155,CONCATENATE(">",$A13))-COUNTIF(data!A$2:A$6155,CONCATENATE(">",$A14))) -> 213 | D14: =SUM(COUNTIF(data!B$2:B$6155,CONCATENATE("=",$A13)),COUNTIF(data!B$2:B$6155,CONCATENATE(">",$A13))-COUNTIF(data!B$2:B$6155,CONCATENATE(">",$A14))) -> 72 | E14: =SUM(COUNTIF(data!C$2:C$6155,CONCATENATE("=",$A13)),COUNTIF(data!C$2:C$6155,CONCATENATE(">",$A13))-COUNTIF(data!C$2:C$6155,CONCATENATE(">",$A14))) -> 272 | F14: =SUM(COUNTIF(data!D$2:D$6155,CONCATENATE("=",$A13)),COUNTIF(data!D$2:D$6155,CONCATENATE(">",$A13))-COUNTIF(data!D$2:D$6155,CONCATENATE(">",$A14))) -> 24
... A34: =A33+0.2 -> 3.4 | B34: =CONCATENATE(ROUND(A33,2),"-",ROUND(A34,2)) -> 3.2-3.4 | C34: =SUM(COUNTIF(data!A$2:A$6155,CONCATENATE("=",$A33)),COUNTIF(data!A$2:A$6155,CONCATENATE(">",$A33))-COUNTIF(data!A$2:A$6155,CONCATENATE(">",$A34))) -> 7 | D34: =SUM(COUNTIF(data!B$2:B$6155,CONCATENATE("=",$A33)),COUNTIF(data!B$2:B$6155,CONCATENATE(">",$A33))-COUNTIF(data!B$2:B$6155,CONCATENATE(">",$A34))) -> 0 | E34: =SUM(COUNTIF(data!C$2:C$6155,CONCATENATE("=",$A33)),COUNTIF(data!C$2:C$6155,CONCATENATE(">",$A33))-COUNTIF(data!C$2:C$6155,CONCATENATE(">",$A34))) -> 1 | F34: =SUM(COUNTIF(data!D$2:D$6155,CONCATENATE("=",$A33)),COUNTIF(data!D$2:D$6155,CONCATENATE(">",$A33))-COUNTIF(data!D$2:D$6155,CONCATENATE(">",$A34))) -> 0
